Workbook

Sheet 00_Титул
A1: Барный калькулятор — заполнен твоими рецептами
A3: Вводные параметры | D3: Как пользоваться
A4: Плановый бюджет, ₽
A5: Плановое кол-во гостей | B5: 15 | D5: 1) На 04_Выбор_меню поставь “Да” нужным позициям и при необходимости задай ручное количество.
A6: Коктейлей на гостя | B6: 1 | D6: 2) На 02_Выходы_рецептов обязательно заполни выходы премиксов/заготовок/настоек.
A7: Шотов на гостя | B7: 1 | D7: 3) На 01_Номенклатура заполни размер упаковки, цену и спорные единицы.
A8: Настоек на гостя | B8: 1 | D8: 4) 09_Список_покупок посчитает закупку и сумму.
A9: Запас на потери / проливы | B9: 0.1

Sheet 01_Номенклатура
A1: Номенклатура | B1: Тип | C1: Базовая ед. | D1: Закупочная ед. | E1: Размер упаковки | F1: Цена упаковки | G1: Коэф. рецепт→база | H1: Комментарий
A2: Игристое | B2: Сырьё | C2: мл | D2: бутылка | E2: 700 | G2: 1
A3: Аперитивы | B3: Сырьё | C3: мл | D3: бутылка | E3: 700 | G3: 1
A4: Содовая | B4: Сырьё | C4: мл | D4: л/бутылка | E4: 1000 | G4: 1
A5: Сироп мохито | B5: Сырьё | C5: мл | D5: л/бутылка | E5: 1000 | G5: 1
A6: Ром | B6: Сырьё | C6: мл | D6: бутылка | E6: 700 | G6: 1
A7: Сок лимона | B7: Сырьё | C7: мл | D7: л/бутылка | E7: 1000 | G7: 1
A8: Мята | B8: Сырьё | C8: шт/веточка | D8: упаковка | G8: 1 | H8: нужно задать пересчёт в г или шт/упаковку
A9: Джин | B9: Сырьё | C9: мл | D9: бутылка | E9: 700 | G9: 1
A10: Клубничный сироп | B10: Заготовка | C10: мл | G10: 1
A11: Пюре маракуйи | B11: Заготовка | C11: мл | G11: 1
A12: Красный базилик | B12: Сырьё | C12: шт/веточка | D12: упаковка | G12: 1 | H12: нужно задать пересчёт в г или шт/упаковку
A13: Арбузный лимонад | B13: Сырьё | C13: мл | D13: л/бутылка | E13: 1000 | G13: 1
A14: Шисо кордиал | B14: Заготовка | C14: мл | G14: 1
A15: Грушевая водка | B15: Сырьё | C15: мл | D15: бутылка | E15: 700 | G15: 1
A16: Сухой вермут | B16: Сырьё | C16: мл | D16: бутылка | E16: 700 | G16: 1
A17: Укроп | B17: Сырьё | C17: шт/веточка | D17: упаковка | G17: 1 | H17: нужно задать пересчёт в г или шт/упаковку
A18: Сахарный сироп | B18: Сырьё | C18: мл | D18: л/бутылка | E18: 1000 | G18: 1
A19: Базилик | B19: Сырьё | C19: шт/веточка | D19: упаковка | G19: 1 | H19: нужно задать пересчёт в г или шт/упаковку
A20: Пюре из персиков | B20: Заготовка | C20: мл | G20: 1
A21: Трипл сек | B21: Сырьё | C21: мл | D21: бутылка | E21: 700 | G21: 1
A22: Мармелад | B22: Заготовка | G22: 1
A23: Пребэч | B23: Заготовка | G23: 1
A24: Клюквенный морс | B24: Сырьё | C24: мл | D24: л/бутылка | E24: 1000 | G24: 1
A25: Джин эстрагоновый | B25: Сырьё | C25: мл | D25: бутылка | E25: 700 | G25: 1
A26: Бабл гам | B26: Заготовка | G26: 1
A27: Сладкий вермут | B27: Сырьё | C27: мл | D27: бутылка | E27: 700 | G27: 1
A28: Маринованный виноград | B28: Сырьё | G28: 1
A29: Амаретто | B29: Сырьё | C29: мл | D29: бутылка | E29: 700 | G29: 1
A30: Щавелевый кордиал | B30: Заготовка | C30: мл | G30: 1
A31: Водка | B31: Сырьё | C31: мл | D31: бутылка | E31: 700 | G31: 1
A32: Ванильная водка | B32: Сырьё | C32: мл | D32: бутылка | E32: 700 | G32: 1
A33: Клубничный джин | B33: Сырьё | C33: мл | D33: бутылка | E33: 700 | G33: 1
A34: Сок лайма | B34: Сырьё | C34: мл | D34: л/бутылка | E34: 1000 | G34: 1
A35: Медовый сироп | B35: Сырьё | C35: мл | D35: л/бутылка | E35: 1000 | G35: 1
A36: Каркаде | B36: Сырьё | C36: г | D36: упаковка/кг | E36: 1000 | G36: 1
A37: Вода | B37: Сырьё | C37: мл | D37: л/бутылка | E37: 1000 | G37: 1
A38: Клубника | B38: Сырьё | C38: г | D38: упаковка/кг | E38: 1000 | G38: 1
A39: Сахар | B39: Сырьё | C39: г | D39: упаковка/кг | E39: 1000 | G39: 1
A40: Киви | B40: Сырьё | C40: г | D40: упаковка/кг | E40: 1000 | G40: 1
...

Sheet 02_Выходы_рецептов
A1: Рецепт | B1: Тип рецепта | C1: Выход рецепта | D1: Ед. выхода | E1: Комментарий
A2: Сприцы | B2: Коктейль | C2: 1 | D2: порция | E2: из старого файла; рецепт на 1 порцию
A3: Мохито | B3: Коктейль | C3: 1 | D3: порция | E3: из старого файла; рецепт на 1 порцию
A4: Клубничная ночь | B4: Коктейль | C4: 1 | D4: порция | E4: из старого файла; рецепт на 1 порцию
A5: Арбуз и маракуйя | B5: Коктейль | C5: 1 | D5: порция | E5: из старого файла; рецепт на 1 порцию
A6: Арбуз и укроп | B6: Коктейль | C6: 1 | D6: порция | E6: из старого файла; рецепт на 1 порцию
A7: Бэзил смэш | B7: Коктейль | C7: 1 | D7: порция | E7: из старого файла; рецепт на 1 порцию
A8: Беллини | B8: Коктейль | C8: 1 | D8: порция | E8: из старого файла; рецепт на 1 порцию
A9: Брекфаст мартини | B9: Коктейль | C9: 1 | D9: порция | E9: из старого файла; рецепт на 1 порцию
A10: COSMOPOLITAN | B10: Коктейль | C10: 1 | D10: порция | E10: из старого файла; рецепт на 1 порцию
A11: Баблгам 4 | B11: Коктейль | C11: 1 | D11: порция | E11: из старого файла; рецепт на 1 порцию
A12: Баблгам 5 | B12: Коктейль | C12: 1 | D12: порция | E12: из старого файла; рецепт на 1 порцию
A13: Баблгам 1 | B13: Коктейль | C13: 1 | D13: порция | E13: из старого файла; рецепт на 1 порцию
... A18: ШОТ 5 | B18: Шот | C18: 1 | D18: порция | E18: из старого файла; рецепт на 1 порцию
A19: Настойка клубника каркаде | B19: Настойка | D19: мл | E19: указать выход одной партии / общий объём настойки
A20: Настойка киви-мята | B20: Настойка | D20: мл | E20: указать выход одной партии / общий объём настойки
A21: Настойка улун-малина | B21: Настойка | D21: мл | E21: указать выход одной партии / общий объём настойки
A22: Настойка клубника корица | B22: Настойка | D22: мл | E22: указать выход одной партии / общий объём настойки
A23: Содовая 1 | B23: Заготовка | D23: мл | E23: указать фактический выход заготовки; без этого сырьё заготовки не раскроется
A24: Клубничный сироп | B24: Заготовка | D24: мл | E24: указать фактический выход заготовки; без этого сырьё заготовки не раскроется
A25: Пюре маракуйи | B25: Заготовка | D25: мл | E25: указать фактический выход заготовки; без этого сырьё заготовки не раскроется
A26: Шисо кордиал | B26: Заготовка | D26: мл | E26: указать фактический выход заготовки; без этого сырьё заготовки не раскроется
A27: Мармелад | B27: Заготовка | D27: мл | E27: указать фактический выход заготовки; без этого сырьё заготовки не раскроется
A28: Пребэч | B28: Заготовка | D28: мл | E28: указать фактический выход заготовки; без этого сырьё заготовки не раскроется
A29: Щавелевый кордиал | B29: Заготовка | D29: мл | E29: указать фактический выход заготовки; без этого сырьё заготовки не раскроется
A30: Бабл гам | B30: Заготовка | D30: мл | E30: указать фактический выход заготовки; без этого сырьё заготовки не раскроется
A31: Пюре из персиков | B31: Заготовка | D31: мл | E31: указать фактический выход заготовки; без этого сырьё заготовки не раскроется

Sheet 03_Рецепты
A1: ID | B1: Рецепт | C1: Тип рецепта | D1: Ингредиент | E1: Тип ингредиента | F1: Кол-во | G1: Ед. | H1: Комментарий | I1: Старый тип | J1: Источник
A2: 1 | B2: Сприцы | C2: Коктейль | D2: Игристое | E2: Сырьё | F2: 90 | G2: мл | I2: алко | J2: Лист4!строка 5
A3: 2 | B3: Сприцы | C3: Коктейль | D3: Аперитивы | E3: Сырьё | F3: 60 | G3: мл | I3: алко | J3: Лист4!строка 6
A4: 3 | B4: Сприцы | C4: Коктейль | D4: Содовая | E4: Сырьё | G4: мл | H4: топом | J4: Лист4!строка 7
A5: 4 | B5: Мохито | C5: Коктейль | D5: Сироп мохито | E5: Сырьё | F5: 35 | G5: мл | I5: покупное | J5: Лист4!строка 8
A6: 5 | B6: Мохито | C6: Коктейль | D6: Ром | E6: Сырьё | F6: 40 | G6: мл | I6: алко | J6: Лист4!строка 9
A7: 6 | B7: Мохито | C7: Коктейль | D7: Сок лимона | E7: Сырьё | F7: 15 | G7: мл | I7: Лимон | J7: Лист4!строка 10
A8: 7 | B8: Мохито | C8: Коктейль | D8: Мята | E8: Сырьё | F8: 10 | G8: шт/веточка | J8: Лист4!строка 11
A9: 8 | B9: Мохито | C9: Коктейль | D9: Содовая | E9: Сырьё | G9: мл | H9: топом | I9: покупное | J9: Лист4!строка 12
A10: 9 | B10: Клубничная ночь | C10: Коктейль | D10: Джин | E10: Сырьё | F10: 40 | G10: мл | I10: алко | J10: Лист4!строка 13
A11: 10 | B11: Клубничная ночь | C11: Коктейль | D11: Сок лимона | E11: Сырьё | F11: 20 | G11: мл | I11: Лимон | J11: Лист4!строка 14
A12: 11 | B12: Клубничная ночь | C12: Коктейль | D12: Содовая | E12: Сырьё | G12: мл | H12: топом | I12: покупное | J12: Лист4!строка 15
A13: 12 | B13: Клубничная ночь | C13: Коктейль | D13: Клубничный сироп | E13: Заготовка | F13: 20 | G13: мл | I13: пребэч | J13: Лист4!строка 16
A14: 13 | B14: Арбуз и маракуйя | C14: Коктейль | D14: Пюре маракуйи | E14: Заготовка | F14: 30 | G14: мл | I14: пребэч | J14: Лист4!строка 17
A15: 14 | B15: Арбуз и маракуйя | C15: Коктейль | D15: Сок лимона | E15: Сырьё | F15: 15 | G15: мл | I15: Лимон | J15: Лист4!строка 18
A16: 15 | B16: Арбуз и маракуйя | C16: Коктейль | D16: Красный базилик | E16: Сырьё | F16: 2 | G16: шт/веточка | I16: покупное | J16: Лист4!строка 19
A17: 16 | B17: Арбуз и маракуйя | C17: Коктейль | D17: Арбузный лимонад | E17: Сырьё | F17: 50 | G17: мл | I17: покупное | J17: Лист4!строка 20
A18: 17 | B18: Арбуз и укроп | C18: Коктейль | D18: Джин | E18: Сырьё | F18: 35 | G18: мл | I18: алко | J18: Лист4!строка 21
A19: 18 | B19: Арбуз и укроп | C19: Коктейль | D19: Шисо кордиал | E19: Заготовка | F19: 25 | G19: мл | I19: пребэч | J19: Лист4!строка 22
A20: 19 | B20: Арбуз и укроп | C20: Коктейль | D20: Грушевая водка | E20: Сырьё | F20: 15 | G20: мл | I20: алко | J20: Лист4!строка 23
A21: 20 | B21: Арбуз и укроп | C21: Коктейль | D21: Сухой вермут | E21: Сырьё | F21: 30 | G21: мл | I21: алко | J21: Лист4!строка 24
A22: 21 | B22: Арбуз и укроп | C22: Коктейль | D22: Укроп | E22: Сырьё | F22: 2 | G22: шт/веточка | I22: покупное | J22: Лист4!строка 25
A23: 22 | B23: Арбуз и укроп | C23: Коктейль | D23: Арбузный лимонад | E23: Сырьё | G23: мл | H23: топом | I23: покупное | J23: Лист4!строка 26
A24: 23 | B24: Бэзил смэш | C24: Коктейль | D24: Сок лимона | E24: Сырьё | F24: 20 | G24: мл | I24: Лимон | J24: Лист4!строка 27
A25: 24 | B25: Бэзил смэш | C25: Коктейль | D25: Джин | E25: Сырьё | F25: 40 | G25: мл | I25: алко | J25: Лист4!строка 28
A26: 25 | B26: Бэзил смэш | C26: Коктейль | D26: Сахарный сироп | E26: Сырьё | F26: 20 | G26: мл | I26: Сахар | J26: Лист4!строка 29
A27: 26 | B27: Бэзил смэш | C27: Коктейль | D27: Базилик | E27: Сырьё | F27: 3 | G27: шт/веточка | I27: покупное | J27: Лист4!строка 30
A28: 27 | B28: Беллини | C28: Коктейль | D28: Игристое | E28: Сырьё | F28: 100 | G28: мл | I28: алко | J28: Лист4!строка 31
A29: 28 | B29: Беллини | C29: Коктейль | D29: Пюре из персиков | E29: Заготовка | F29: 50 | G29: мл | I29: пребэч | J29: Лист4!строка 32
A30: 29 | B30: Брекфаст мартини | C30: Коктейль | D30: Джин | E30: Сырьё | F30: 50 | G30: мл | I30: алко | J30: Лист4!строка 33
A31: 30 | B31: Брекфаст мартини | C31: Коктейль | D31: Трипл сек | E31: Сырьё | F31: 15 | G31: мл | I31: алко | J31: Лист4!строка 34
A32: 31 | B32: Брекфаст мартини | C32: Коктейль | D32: Сок лимона | E32: Сырьё | F32: 15 | G32: мл | I32: Лимон | J32: Лист4!строка 35
A33: 32 | B33: Брекфаст мартини | C33: Коктейль | D33: Мармелад | E33: Заготовка | F33: 1 | I33: пребэч | J33: Лист4!строка 36
A34: 33 | B34: COSMOPOLITAN | C34: Коктейль | D34: Пребэч | E34: Заготовка | F34: 60 | I34: пребэч | J34: Лист4!строка 37
A35: 34 | B35: COSMOPOLITAN | C35: Коктейль | D35: Сок лимона | E35: Сырьё | F35: 20 | G35: мл | I35: Лимон | J35: Лист4!строка 38
A36: 35 | B36: COSMOPOLITAN | C36: Коктейль | D36: Трипл сек | E36: Сырьё | F36: 10 | G36: мл | I36: алко | J36: Лист4!строка 39
A37: 36 | B37: COSMOPOLITAN | C37: Коктейль | D37: Клюквенный морс | E37: Сырьё | F37: 20 | G37: мл | I37: покупное | J37: Лист4!строка 40
A38: 37 | B38: Баблгам 4 | C38: Коктейль | D38: Джин эстрагоновый | E38: Сырьё | F38: 40 | G38: мл | I38: алко | J38: Лист4!строка 41
A39: 38 | B39: Баблгам 4 | C39: Коктейль | D39: Бабл гам | E39: Заготовка | F39: 20 | I39: пребэч | J39: Лист4!строка 42
A40: 39 | B40: Баблгам 4 | C40: Коктейль | D40: Сухой вермут | E40: Сырьё | F40: 15 | G40: мл | I40: алко | J40: Лист4!строка 43
...

Sheet 04_Выбор_меню
A1: Позиция | B1: Тип | C1: Включить | D1: Ручное кол-во | E1: Авто кол-во | F1: Итого к выпуску | G1: Комментарий
A2: Сприцы | B2: Коктейль | C2: Да | E2: =IF(C2<>"Да",0,IF(B2="Коктейль",'00_Титул'!$B$5*'00_Титул'!$B$6/MAX(1,COUNTIFS($C:$C,"Да",$B:$B,"Коктейль")),IF(B2="Шот",'00_Титул'!$B$5*'00_Титул'!$B$7/MAX(1,COUNTIFS($C:$C,"Да",$B:$B,"Шот")),IF(B2="Настойка",'00_Титул'!$B$5*'00_Титул'!$B$8/MAX(1,COUNTIFS($C:$C,"Да",$B:$B,"Настойка")),0)))) -> 0 | F2: =IF(D2<>"",D2,E2)*(1+'00_Титул'!$B$9) -> 0
A3: Мохито | B3: Коктейль | C3: Да | E3: =IF(C3<>"Да",0,IF(B3="Коктейль",'00_Титул'!$B$5*'00_Титул'!$B$6/MAX(1,COUNTIFS($C:$C,"Да",$B:$B,"Коктейль")),IF(B3="Шот",'00_Титул'!$B$5*'00_Титул'!$B$7/MAX(1,COUNTIFS($C:$C,"Да",$B:$B,"Шот")),IF(B3="Настойка",'00_Титул'!$B$5*'00_Титул'!$B$8/MAX(1,COUNTIFS($C:$C,"Да",$B:$B,"Настойка")),0)))) -> 0 | F3: =IF(D3<>"",D3,E3)*(1+'00_Титул'!$B$9) -> 0
A4: Клубничная ночь | B4: Коктейль | C4: Да | E4: =IF(C4<>"Да",0,IF(B4="Коктейль",'00_Титул'!$B$5*'00_Титул'!$B$6/MAX(1,COUNTIFS($C:$C,"Да",$B:$B,"Коктейль")),IF(B4="Шот",'00_Титул'!$B$5*'00_Титул'!$B$7/MAX(1,COUNTIFS($C:$C,"Да",$B:$B,"Шот")),IF(B4="Настойка",'00_Титул'!$B$5*'00_Титул'!$B$8/MAX(1,COUNTIFS($C:$C,"Да",$B:$B,"Настойка")),0)))) -> 0 | F4: =IF(D4<>"",D4,E4)*(1+'00_Титул'!$B$9) -> 0
A5: Арбуз и маракуйя | B5: Коктейль | C5: Да | E5: =IF(C5<>"Да",0,IF(B5="Коктейль",'00_Титул'!$B$5*'00_Титул'!$B$6/MAX(1,COUNTIFS($C:$C,"Да",$B:$B,"Коктейль")),IF(B5="Шот",'00_Титул'!$B$5*'00_Титул'!$B$7/MAX(1,COUNTIFS($C:$C,"Да",$B:$B,"Шот")),IF(B5="Настойка",'00_Титул'!$B$5*'00_Титул'!$B$8/MAX(1,COUNTIFS($C:$C,"Да",$B:$B,"Настойка")),0)))) -> 0 | F5: =IF(D5<>"",D5,E5)*(1+'00_Титул'!$B$9) -> 0
A6: Арбуз и укроп | B6: Коктейль | C6: Да | E6: =IF(C6<>"Да",0,IF(B6="Коктейль",'00_Титул'!$B$5*'00_Титул'!$B$6/MAX(1,COUNTIFS($C:$C,"Да",$B:$B,"Коктейль")),IF(B6="Шот",'00_Титул'!$B$5*'00_Титул'!$B$7/MAX(1,COUNTIFS($C:$C,"Да",$B:$B,"Шот")),IF(B6="Настойка",'00_Титул'!$B$5*'00_Титул'!$B$8/MAX(1,COUNTIFS($C:$C,"Да",$B:$B,"Настойка")),0)))) -> 0 | F6: =IF(D6<>"",D6,E6)*(1+'00_Титул'!$B$9) -> 0
A7: Бэзил смэш | B7: Коктейль | C7: Да | E7: =IF(C7<>"Да",0,IF(B7="Коктейль",'00_Титул'!$B$5*'00_Титул'!$B$6/MAX(1,COUNTIFS($C:$C,"Да",$B:$B,"Коктейль")),IF(B7="Шот",'00_Титул'!$B$5*'00_Титул'!$B$7/MAX(1,COUNTIFS($C:$C,"Да",$B:$B,"Шот")),IF(B7="Настойка",'00_Титул'!$B$5*'00_Титул'!$B$8/MAX(1,COUNTIFS($C:$C,"Да",$B:$B,"Настойка")),0)))) -> 0 | F7: =IF(D7<>"",D7,E7)*(1+'00_Титул'!$B$9) -> 0
A8: Беллини | B8: Коктейль | C8: Да | E8: =IF(C8<>"Да",0,IF(B8="Коктейль",'00_Титул'!$B$5*'00_Титул'!$B$6/MAX(1,COUNTIFS($C:$C,"Да",$B:$B,"Коктейль")),IF(B8="Шот",'00_Титул'!$B$5*'00_Титул'!$B$7/MAX(1,COUNTIFS($C:$C,"Да",$B:$B,"Шот")),IF(B8="Настойка",'00_Титул'!$B$5*'00_Титул'!$B$8/MAX(1,COUNTIFS($C:$C,"Да",$B:$B,"Настойка")),0)))) -> 0 | F8: =IF(D8<>"",D8,E8)*(1+'00_Титул'!$B$9) -> 0
A9: Брекфаст мартини | B9: Коктейль | C9: Да | E9: =IF(C9<>"Да",0,IF(B9="Коктейль",'00_Титул'!$B$5*'00_Титул'!$B$6/MAX(1,COUNTIFS($C:$C,"Да",$B:$B,"Коктейль")),IF(B9="Шот",'00_Титул'!$B$5*'00_Титул'!$B$7/MAX(1,COUNTIFS($C:$C,"Да",$B:$B,"Шот")),IF(B9="Настойка",'00_Титул'!$B$5*'00_Титул'!$B$8/MAX(1,COUNTIFS($C:$C,"Да",$B:$B,"Настойка")),0)))) -> 0 | F9: =IF(D9<>"",D9,E9)*(1+'00_Титул'!$B$9) -> 0
A10: COSMOPOLITAN | B10: Коктейль | C10: Да | E10: =IF(C10<>"Да",0,IF(B10="Коктейль",'00_Титул'!$B$5*'00_Титул'!$B$6/MAX(1,COUNTIFS($C:$C,"Да",$B:$B,"Коктейль")),IF(B10="Шот",'00_Титул'!$B$5*'00_Титул'!$B$7/MAX(1,COUNTIFS($C:$C,"Да",$B:$B,"Шот")),IF(B10="Настойка",'00_Титул'!$B$5*'00_Титул'!$B$8/MAX(1,COUNTIFS($C:$C,"Да",$B:$B,"Настойка")),0)))) -> 0 | F10: =IF(D10<>"",D10,E10)*(1+'00_Титул'!$B$9) -> 0
A11: Баблгам 4 | B11: Коктейль | C11: Да | E11: =IF(C11<>"Да",0,IF(B11="Коктейль",'00_Титул'!$B$5*'00_Титул'!$B$6/MAX(1,COUNTIFS($C:$C,"Да",$B:$B,"Коктейль")),IF(B11="Шот",'00_Титул'!$B$5*'00_Титул'!$B$7/MAX(1,COUNTIFS($C:$C,"Да",$B:$B,"Шот")),IF(B11="Настойка",'00_Титул'!$B$5*'00_Титул'!$B$8/MAX(1,COUNTIFS($C:$C,"Да",$B:$B,"Настойка")),0)))) -> 0 | F11: =IF(D11<>"",D11,E11)*(1+'00_Титул'!$B$9) -> 0
A12: Баблгам 5 | B12: Коктейль | C12: Да | E12: =IF(C12<>"Да",0,IF(B12="Коктейль",'00_Титул'!$B$5*'00_Титул'!$B$6/MAX(1,COUNTIFS($C:$C,"Да",$B:$B,"Коктейль")),IF(B12="Шот",'00_Титул'!$B$5*'00_Титул'!$B$7/MAX(1,COUNTIFS($C:$C,"Да",$B:$B,"Шот")),IF(B12="Настойка",'00_Титул'!$B$5*'00_Титул'!$B$8/MAX(1,COUNTIFS($C:$C,"Да",$B:$B,"Настойка")),0)))) -> 0 | F12: =IF(D12<>"",D12,E12)*(1+'00_Титул'!$B$9) -> 0
A13: Баблгам 1 | B13: Коктейль | C13: Да | E13: =IF(C13<>"Да",0,IF(B13="Коктейль",'00_Титул'!$B$5*'00_Титул'!$B$6/MAX(1,COUNTIFS($C:$C,"Да",$B:$B,"Коктейль")),IF(B13="Шот",'00_Титул'!$B$5*'00_Титул'!$B$7/MAX(1,COUNTIFS($C:$C,"Да",$B:$B,"Шот")),IF(B13="Настойка",'00_Титул'!$B$5*'00_Титул'!$B$8/MAX(1,COUNTIFS($C:$C,"Да",$B:$B,"Настойка")),0)))) -> 0 | F13: =IF(D13<>"",D13,E13)*(1+'00_Титул'!$B$9) -> 0
... A22: Настойка клубника корица | B22: Настойка | C22: Да | E22: =IF(C22<>"Да",0,IF(B22="Коктейль",'00_Титул'!$B$5*'00_Титул'!$B$6/MAX(1,COUNTIFS($C:$C,"Да",$B:$B,"Коктейль")),IF(B22="Шот",'00_Титул'!$B$5*'00_Титул'!$B$7/MAX(1,COUNTIFS($C:$C,"Да",$B:$B,"Шот")),IF(B22="Настойка",'00_Титул'!$B$5*'00_Титул'!$B$8/MAX(1,COUNTIFS($C:$C,"Да",$B:$B,"Настойка")),0)))) -> 0 | F22: =IF(D22<>"",D22,E22)*(1+'00_Титул'!$B$9) -> 0

Sheet 05_Расход_меню
A1: Рецепт | B1: Тип рецепта | C1: Ингредиент | D1: Тип ингредиента | E1: Кол-во в рецепте | F1: Ед. | G1: Кол-во выпуск | H1: Итого нужно | I1: Комментарий
A2: Сприцы | B2: Коктейль | C2: Игристое | D2: Сырьё | E2: 90 | F2: мл | G2: =SUMIF('04_Выбор_меню'!$A:$A,A2,'04_Выбор_меню'!$F:$F) -> 0 | H2: =E2*G2 -> 0
A3: Сприцы | B3: Коктейль | C3: Аперитивы | D3: Сырьё | E3: 60 | F3: мл | G3: =SUMIF('04_Выбор_меню'!$A:$A,A3,'04_Выбор_меню'!$F:$F) -> 0 | H3: =E3*G3 -> 0
A4: Сприцы | B4: Коктейль | C4: Содовая | D4: Сырьё | F4: мл | G4: =SUMIF('04_Выбор_меню'!$A:$A,A4,'04_Выбор_меню'!$F:$F) -> 0 | I4: топом
A5: Мохито | B5: Коктейль | C5: Сироп мохито | D5: Сырьё | E5: 35 | F5: мл | G5: =SUMIF('04_Выбор_меню'!$A:$A,A5,'04_Выбор_меню'!$F:$F) -> 0 | H5: =E5*G5 -> 0
A6: Мохито | B6: Коктейль | C6: Ром | D6: Сырьё | E6: 40 | F6: мл | G6: =SUMIF('04_Выбор_меню'!$A:$A,A6,'04_Выбор_меню'!$F:$F) -> 0 | H6: =E6*G6 -> 0
A7: Мохито | B7: Коктейль | C7: Сок лимона | D7: Сырьё | E7: 15 | F7: мл | G7: =SUMIF('04_Выбор_меню'!$A:$A,A7,'04_Выбор_меню'!$F:$F) -> 0 | H7: =E7*G7 -> 0
A8: Мохито | B8: Коктейль | C8: Мята | D8: Сырьё | E8: 10 | F8: шт/веточка | G8: =SUMIF('04_Выбор_меню'!$A:$A,A8,'04_Выбор_меню'!$F:$F) -> 0 | H8: =E8*G8 -> 0
A9: Мохито | B9: Коктейль | C9: Содовая | D9: Сырьё | F9: мл | G9: =SUMIF('04_Выбор_меню'!$A:$A,A9,'04_Выбор_меню'!$F:$F) -> 0 | I9: топом
A10: Клубничная ночь | B10: Коктейль | C10: Джин | D10: Сырьё | E10: 40 | F10: мл | G10: =SUMIF('04_Выбор_меню'!$A:$A,A10,'04_Выбор_меню'!$F:$F) -> 0 | H10: =E10*G10 -> 0
A11: Клубничная ночь | B11: Коктейль | C11: Сок лимона | D11: Сырьё | E11: 20 | F11: мл | G11: =SUMIF('04_Выбор_меню'!$A:$A,A11,'04_Выбор_меню'!$F:$F) -> 0 | H11: =E11*G11 -> 0
A12: Клубничная ночь | B12: Коктейль | C12: Содовая | D12: Сырьё | F12: мл | G12: =SUMIF('04_Выбор_меню'!$A:$A,A12,'04_Выбор_меню'!$F:$F) -> 0 | I12: топом
A13: Клубничная ночь | B13: Коктейль | C13: Клубничный сироп | D13: Заготовка | E13: 20 | F13: мл | G13: =SUMIF('04_Выбор_меню'!$A:$A,A13,'04_Выбор_меню'!$F:$F) -> 0 | H13: =E13*G13 -> 0
A14: Арбуз и маракуйя | B14: Коктейль | C14: Пюре маракуйи | D14: Заготовка | E14: 30 | F14: мл | G14: =SUMIF('04_Выбор_меню'!$A:$A,A14,'04_Выбор_меню'!$F:$F) -> 0 | H14: =E14*G14 -> 0
A15: Арбуз и маракуйя | B15: Коктейль | C15: Сок лимона | D15: Сырьё | E15: 15 | F15: мл | G15: =SUMIF('04_Выбор_меню'!$A:$A,A15,'04_Выбор_меню'!$F:$F) -> 0 | H15: =E15*G15 -> 0
A16: Арбуз и маракуйя | B16: Коктейль | C16: Красный базилик | D16: Сырьё | E16: 2 | F16: шт/веточка | G16: =SUMIF('04_Выбор_меню'!$A:$A,A16,'04_Выбор_меню'!$F:$F) -> 0 | H16: =E16*G16 -> 0
A17: Арбуз и маракуйя | B17: Коктейль | C17: Арбузный лимонад | D17: Сырьё | E17: 50 | F17: мл | G17: =SUMIF('04_Выбор_меню'!$A:$A,A17,'04_Выбор_меню'!$F:$F) -> 0 | H17: =E17*G17 -> 0
A18: Арбуз и укроп | B18: Коктейль | C18: Джин | D18: Сырьё | E18: 35 | F18: мл | G18: =SUMIF('04_Выбор_меню'!$A:$A,A18,'04_Выбор_меню'!$F:$F) -> 0 | H18: =E18*G18 -> 0
A19: Арбуз и укроп | B19: Коктейль | C19: Шисо кордиал | D19: Заготовка | E19: 25 | F19: мл | G19: =SUMIF('04_Выбор_меню'!$A:$A,A19,'04_Выбор_меню'!$F:$F) -> 0 | H19: =E19*G19 -> 0
A20: Арбуз и укроп | B20: Коктейль | C20: Грушевая водка | D20: Сырьё | E20: 15 | F20: мл | G20: =SUMIF('04_Выбор_меню'!$A:$A,A20,'04_Выбор_меню'!$F:$F) -> 0 | H20: =E20*G20 -> 0
A21: Арбуз и укроп | B21: Коктейль | C21: Сухой вермут | D21: Сырьё | E21: 30 | F21: мл | G21: =SUMIF('04_Выбор_меню'!$A:$A,A21,'04_Выбор_меню'!$F:$F) -> 0 | H21: =E21*G21 -> 0
A22: Арбуз и укроп | B22: Коктейль | C22: Укроп | D22: Сырьё | E22: 2 | F22: шт/веточка | G22: =SUMIF('04_Выбор_меню'!$A:$A,A22,'04_Выбор_меню'!$F:$F) -> 0 | H22: =E22*G22 -> 0
A23: Арбуз и укроп | B23: Коктейль | C23: Арбузный лимонад | D23: Сырьё | F23: мл | G23: =SUMIF('04_Выбор_меню'!$A:$A,A23,'04_Выбор_меню'!$F:$F) -> 0 | I23: топом
A24: Бэзил смэш | B24: Коктейль | C24: Сок лимона | D24: Сырьё | E24: 20 | F24: мл | G24: =SUMIF('04_Выбор_меню'!$A:$A,A24,'04_Выбор_меню'!$F:$F) -> 0 | H24: =E24*G24 -> 0
A25: Бэзил смэш | B25: Коктейль | C25: Джин | D25: Сырьё | E25: 40 | F25: мл | G25: =SUMIF('04_Выбор_меню'!$A:$A,A25,'04_Выбор_меню'!$F:$F) -> 0 | H25: =E25*G25 -> 0
A26: Бэзил смэш | B26: Коктейль | C26: Сахарный сироп | D26: Сырьё | E26: 20 | F26: мл | G26: =SUMIF('04_Выбор_меню'!$A:$A,A26,'04_Выбор_меню'!$F:$F) -> 0 | H26: =E26*G26 -> 0
A27: Бэзил смэш | B27: Коктейль | C27: Базилик | D27: Сырьё | E27: 3 | F27: шт/веточка | G27: =SUMIF('04_Выбор_меню'!$A:$A,A27,'04_Выбор_меню'!$F:$F) -> 0 | H27: =E27*G27 -> 0
A28: Беллини | B28: Коктейль | C28: Игристое | D28: Сырьё | E28: 100 | F28: мл | G28: =SUMIF('04_Выбор_меню'!$A:$A,A28,'04_Выбор_меню'!$F:$F) -> 0 | H28: =E28*G28 -> 0
A29: Беллини | B29: Коктейль | C29: Пюре из персиков | D29: Заготовка | E29: 50 | F29: мл | G29: =SUMIF('04_Выбор_меню'!$A:$A,A29,'04_Выбор_меню'!$F:$F) -> 0 | H29: =E29*G29 -> 0
A30: Брекфаст мартини | B30: Коктейль | C30: Джин | D30: Сырьё | E30: 50 | F30: мл | G30: =SUMIF('04_Выбор_меню'!$A:$A,A30,'04_Выбор_меню'!$F:$F) -> 0 | H30: =E30*G30 -> 0
A31: Брекфаст мартини | B31: Коктейль | C31: Трипл сек | D31: Сырьё | E31: 15 | F31: мл | G31: =SUMIF('04_Выбор_меню'!$A:$A,A31,'04_Выбор_меню'!$F:$F) -> 0 | H31: =E31*G31 -> 0
A32: Брекфаст мартини | B32: Коктейль | C32: Сок лимона | D32: Сырьё | E32: 15 | F32: мл | G32: =SUMIF('04_Выбор_меню'!$A:$A,A32,'04_Выбор_меню'!$F:$F) -> 0 | H32: =E32*G32 -> 0
A33: Брекфаст мартини | B33: Коктейль | C33: Мармелад | D33: Заготовка | E33: 1 | G33: =SUMIF('04_Выбор_меню'!$A:$A,A33,'04_Выбор_меню'!$F:$F) -> 0 | H33: =E33*G33 -> 0
A34: COSMOPOLITAN | B34: Коктейль | C34: Пребэч | D34: Заготовка | E34: 60 | G34: =SUMIF('04_Выбор_меню'!$A:$A,A34,'04_Выбор_меню'!$F:$F) -> 0 | H34: =E34*G34 -> 0
A35: COSMOPOLITAN | B35: Коктейль | C35: Сок лимона | D35: Сырьё | E35: 20 | F35: мл | G35: =SUMIF('04_Выбор_меню'!$A:$A,A35,'04_Выбор_меню'!$F:$F) -> 0 | H35: =E35*G35 -> 0
A36: COSMOPOLITAN | B36: Коктейль | C36: Трипл сек | D36: Сырьё | E36: 10 | F36: мл | G36: =SUMIF('04_Выбор_меню'!$A:$A,A36,'04_Выбор_меню'!$F:$F) -> 0 | H36: =E36*G36 -> 0
A37: COSMOPOLITAN | B37: Коктейль | C37: Клюквенный морс | D37: Сырьё | E37: 20 | F37: мл | G37: =SUMIF('04_Выбор_меню'!$A:$A,A37,'04_Выбор_меню'!$F:$F) -> 0 | H37: =E37*G37 -> 0
A38: Баблгам 4 | B38: Коктейль | C38: Джин эстрагоновый | D38: Сырьё | E38: 40 | F38: мл | G38: =SUMIF('04_Выбор_меню'!$A:$A,A38,'04_Выбор_меню'!$F:$F) -> 0 | H38: =E38*G38 -> 0
A39: Баблгам 4 | B39: Коктейль | C39: Бабл гам | D39: Заготовка | E39: 20 | G39: =SUMIF('04_Выбор_меню'!$A:$A,A39,'04_Выбор_меню'!$F:$F) -> 0 | H39: =E39*G39 -> 0
A40: Баблгам 4 | B40: Коктейль | C40: Сухой вермут | D40: Сырьё | E40: 15 | F40: мл | G40: =SUMIF('04_Выбор_меню'!$A:$A,A40,'04_Выбор_меню'!$F:$F) -> 0 | H40: =E40*G40 -> 0
...

Sheet 06_Нужно_заготовок
A1: Заготовка | B1: Нужно из меню | C1: Ед. | D1: Выход рецепта | E1: Коэф. партий | F1: Статус
A2: Содовая 1 | B2: =SUMIFS('05_Расход_меню'!$H:$H,'05_Расход_меню'!$C:$C,A2) -> 0 | C2: =IFERROR(INDEX('02_Выходы_рецептов'!$D:$D,MATCH(A2,'02_Выходы_рецептов'!$A:$A,0)),"") -> 0 | D2: =IFERROR(INDEX('02_Выходы_рецептов'!$C:$C,MATCH(A2,'02_Выходы_рецептов'!$A:$A,0)),"") -> 0 | E2: =IF(OR(B2=0,D2=""),0,B2/D2) -> 0 | F2: =IF(B2=0,"не используется",IF(D2="","указать выход","ок")) -> 0
A3: Клубничный сироп | B3: =SUMIFS('05_Расход_меню'!$H:$H,'05_Расход_меню'!$C:$C,A3) -> 0 | C3: =IFERROR(INDEX('02_Выходы_рецептов'!$D:$D,MATCH(A3,'02_Выходы_рецептов'!$A:$A,0)),"") -> 0 | D3: =IFERROR(INDEX('02_Выходы_рецептов'!$C:$C,MATCH(A3,'02_Выходы_рецептов'!$A:$A,0)),"") -> 0 | E3: =IF(OR(B3=0,D3=""),0,B3/D3) -> 0 | F3: =IF(B3=0,"не используется",IF(D3="","указать выход","ок")) -> 0
A4: Пюре маракуйи | B4: =SUMIFS('05_Расход_меню'!$H:$H,'05_Расход_меню'!$C:$C,A4) -> 0 | C4: =IFERROR(INDEX('02_Выходы_рецептов'!$D:$D,MATCH(A4,'02_Выходы_рецептов'!$A:$A,0)),"") -> 0 | D4: =IFERROR(INDEX('02_Выходы_рецептов'!$C:$C,MATCH(A4,'02_Выходы_рецептов'!$A:$A,0)),"") -> 0 | E4: =IF(OR(B4=0,D4=""),0,B4/D4) -> 0 | F4: =IF(B4=0,"не используется",IF(D4="","указать выход","ок")) -> 0
A5: Шисо кордиал | B5: =SUMIFS('05_Расход_меню'!$H:$H,'05_Расход_меню'!$C:$C,A5) -> 0 | C5: =IFERROR(INDEX('02_Выходы_рецептов'!$D:$D,MATCH(A5,'02_Выходы_рецептов'!$A:$A,0)),"") -> 0 | D5: =IFERROR(INDEX('02_Выходы_рецептов'!$C:$C,MATCH(A5,'02_Выходы_рецептов'!$A:$A,0)),"") -> 0 | E5: =IF(OR(B5=0,D5=""),0,B5/D5) -> 0 | F5: =IF(B5=0,"не используется",IF(D5="","указать выход","ок")) -> 0
A6: Мармелад | B6: =SUMIFS('05_Расход_меню'!$H:$H,'05_Расход_меню'!$C:$C,A6) -> 0 | C6: =IFERROR(INDEX('02_Выходы_рецептов'!$D:$D,MATCH(A6,'02_Выходы_рецептов'!$A:$A,0)),"") -> 0 | D6: =IFERROR(INDEX('02_Выходы_рецептов'!$C:$C,MATCH(A6,'02_Выходы_рецептов'!$A:$A,0)),"") -> 0 | E6: =IF(OR(B6=0,D6=""),0,B6/D6) -> 0 | F6: =IF(B6=0,"не используется",IF(D6="","указать выход","ок")) -> 0
A7: Пребэч | B7: =SUMIFS('05_Расход_меню'!$H:$H,'05_Расход_меню'!$C:$C,A7) -> 0 | C7: =IFERROR(INDEX('02_Выходы_рецептов'!$D:$D,MATCH(A7,'02_Выходы_рецептов'!$A:$A,0)),"") -> 0 | D7: =IFERROR(INDEX('02_Выходы_рецептов'!$C:$C,MATCH(A7,'02_Выходы_рецептов'!$A:$A,0)),"") -> 0 | E7: =IF(OR(B7=0,D7=""),0,B7/D7) -> 0 | F7: =IF(B7=0,"не используется",IF(D7="","указать выход","ок")) -> 0
A8: Щавелевый кордиал | B8: =SUMIFS('05_Расход_меню'!$H:$H,'05_Расход_меню'!$C:$C,A8) -> 0 | C8: =IFERROR(INDEX('02_Выходы_рецептов'!$D:$D,MATCH(A8,'02_Выходы_рецептов'!$A:$A,0)),"") -> 0 | D8: =IFERROR(INDEX('02_Выходы_рецептов'!$C:$C,MATCH(A8,'02_Выходы_рецептов'!$A:$A,0)),"") -> 0 | E8: =IF(OR(B8=0,D8=""),0,B8/D8) -> 0 | F8: =IF(B8=0,"не используется",IF(D8="","указать выход","ок")) -> 0
A9: Бабл гам | B9: =SUMIFS('05_Расход_меню'!$H:$H,'05_Расход_меню'!$C:$C,A9) -> 0 | C9: =IFERROR(INDEX('02_Выходы_рецептов'!$D:$D,MATCH(A9,'02_Выходы_рецептов'!$A:$A,0)),"") -> 0 | D9: =IFERROR(INDEX('02_Выходы_рецептов'!$C:$C,MATCH(A9,'02_Выходы_рецептов'!$A:$A,0)),"") -> 0 | E9: =IF(OR(B9=0,D9=""),0,B9/D9) -> 0 | F9: =IF(B9=0,"не используется",IF(D9="","указать выход","ок")) -> 0
A10: Пюре из персиков | B10: =SUMIFS('05_Расход_меню'!$H:$H,'05_Расход_меню'!$C:$C,A10) -> 0 | C10: =IFERROR(INDEX('02_Выходы_рецептов'!$D:$D,MATCH(A10,'02_Выходы_рецептов'!$A:$A,0)),"") -> 0 | D10: =IFERROR(INDEX('02_Выходы_рецептов'!$C:$C,MATCH(A10,'02_Выходы_рецептов'!$A:$A,0)),"") -> 0 | E10: =IF(OR(B10=0,D10=""),0,B10/D10) -> 0 | F10: =IF(B10=0,"не используется",IF(D10="","указать выход","ок")) -> 0

Sheet 07_Расход_заготовок
A1: Заготовка | B1: Ингредиент | C1: Тип ингредиента | D1: Кол-во в рецепте | E1: Ед. | F1: Коэф. партий | G1: Итого нужно | H1: Комментарий
A2: Содовая 1 | B2: Молочный улун | C2: Сырьё | D2: 10 | E2: г | F2: =SUMIF('06_Нужно_заготовок'!$A:$A,A2,'06_Нужно_заготовок'!$E:$E) -> 0 | G2: =D2*F2 -> 0
A3: Содовая 1 | B3: Вода | C3: Сырьё | D3: 1000 | E3: мл | F3: =SUMIF('06_Нужно_заготовок'!$A:$A,A3,'06_Нужно_заготовок'!$E:$E) -> 0 | G3: =D3*F3 -> 0
A4: Содовая 1 | B4: Дынный аром-р | C4: Сырьё | D4: 2.5 | E4: мл | F4: =SUMIF('06_Нужно_заготовок'!$A:$A,A4,'06_Нужно_заготовок'!$E:$E) -> 0 | G4: =D4*F4 -> 0
A5: Содовая 1 | B5: Соль | C5: Сырьё | D5: 0.3 | E5: г | F5: =SUMIF('06_Нужно_заготовок'!$A:$A,A5,'06_Нужно_заготовок'!$E:$E) -> 0 | G5: =D5*F5 -> 0
A6: Содовая 1 | B6: Аскорбиновая к-та | C6: Сырьё | D6: 1.5 | E6: г | F6: =SUMIF('06_Нужно_заготовок'!$A:$A,A6,'06_Нужно_заготовок'!$E:$E) -> 0 | G6: =D6*F6 -> 0
A7: Клубничный сироп | B7: Клубника | C7: Сырьё | D7: 140 | E7: г | F7: =SUMIF('06_Нужно_заготовок'!$A:$A,A7,'06_Нужно_заготовок'!$E:$E) -> 0 | G7: =D7*F7 -> 0
A8: Клубничный сироп | B8: Мёд | C8: Сырьё | D8: 140 | E8: г | F8: =SUMIF('06_Нужно_заготовок'!$A:$A,A8,'06_Нужно_заготовок'!$E:$E) -> 0 | G8: =D8*F8 -> 0
A9: Пюре маракуйи | B9: Маракуйя | C9: Сырьё | D9: 1000 | E9: г | F9: =SUMIF('06_Нужно_заготовок'!$A:$A,A9,'06_Нужно_заготовок'!$E:$E) -> 0 | G9: =D9*F9 -> 0
A10: Пюре маракуйи | B10: Сахар | C10: Сырьё | E10: г | F10: =SUMIF('06_Нужно_заготовок'!$A:$A,A10,'06_Нужно_заготовок'!$E:$E) -> 0 | H10: 250-400
A11: Пюре маракуйи | B11: Вода | C11: Сырьё | E11: мл | F11: =SUMIF('06_Нужно_заготовок'!$A:$A,A11,'06_Нужно_заготовок'!$E:$E) -> 0 | H11: 250-400
A12: Шисо кордиал | B12: Шисо листья | C12: Сырьё | D12: 25 | F12: =SUMIF('06_Нужно_заготовок'!$A:$A,A12,'06_Нужно_заготовок'!$E:$E) -> 0 | G12: =D12*F12 -> 0
A13: Шисо кордиал | B13: Сахарный сироп | C13: Сырьё | D13: 400 | E13: мл | F13: =SUMIF('06_Нужно_заготовок'!$A:$A,A13,'06_Нужно_заготовок'!$E:$E) -> 0 | G13: =D13*F13 -> 0
A14: Шисо кордиал | B14: Раствор яблочной к-ты | C14: Сырьё | D14: 600 | E14: мл | F14: =SUMIF('06_Нужно_заготовок'!$A:$A,A14,'06_Нужно_заготовок'!$E:$E) -> 0 | G14: =D14*F14 -> 0
A15: Мармелад | B15: Красные апельсины | C15: Сырьё | D15: 500 | E15: г | F15: =SUMIF('06_Нужно_заготовок'!$A:$A,A15,'06_Нужно_заготовок'!$E:$E) -> 0 | G15: =D15*F15 -> 0
A16: Мармелад | B16: Лемонграсс | C16: Сырьё | D16: 50 | E16: г | F16: =SUMIF('06_Нужно_заготовок'!$A:$A,A16,'06_Нужно_заготовок'!$E:$E) -> 0 | G16: =D16*F16 -> 0
A17: Мармелад | B17: Севен Ап | C17: Сырьё | D17: 500 | E17: мл | F17: =SUMIF('06_Нужно_заготовок'!$A:$A,A17,'06_Нужно_заготовок'!$E:$E) -> 0 | G17: =D17*F17 -> 0
A18: Мармелад | B18: Сахар | C18: Сырьё | D18: 300 | E18: г | F18: =SUMIF('06_Нужно_заготовок'!$A:$A,A18,'06_Нужно_заготовок'!$E:$E) -> 0 | G18: =D18*F18 -> 0
A19: Мармелад | B19: Лимонная к-та | C19: Сырьё | D19: 1 | E19: г | F19: =SUMIF('06_Нужно_заготовок'!$A:$A,A19,'06_Нужно_заготовок'!$E:$E) -> 0 | G19: =D19*F19 -> 0
A20: Пребэч | B20: Пилы лайма | C20: Сырьё | D20: 3 | E20: шт | F20: =SUMIF('06_Нужно_заготовок'!$A:$A,A20,'06_Нужно_заготовок'!$E:$E) -> 0 | G20: =D20*F20 -> 0
A21: Пребэч | B21: Пилы апельсина | C21: Сырьё | D21: 4 | E21: шт | F21: =SUMIF('06_Нужно_заготовок'!$A:$A,A21,'06_Нужно_заготовок'!$E:$E) -> 0 | G21: =D21*F21 -> 0
A22: Пребэч | B22: Пилы грейпфрута | C22: Сырьё | D22: 2 | E22: шт | F22: =SUMIF('06_Нужно_заготовок'!$A:$A,A22,'06_Нужно_заготовок'!$E:$E) -> 0 | G22: =D22*F22 -> 0
A23: Пребэч | B23: Малина | C23: Сырьё | D23: 100 | E23: г | F23: =SUMIF('06_Нужно_заготовок'!$A:$A,A23,'06_Нужно_заготовок'!$E:$E) -> 0 | G23: =D23*F23 -> 0
A24: Пребэч | B24: Джин | C24: Сырьё | D24: 100 | E24: мл | F24: =SUMIF('06_Нужно_заготовок'!$A:$A,A24,'06_Нужно_заготовок'!$E:$E) -> 0 | G24: =D24*F24 -> 0
... A46: Пюре из персиков | B46: Ром/водка | C46: Сырьё | D46: 30 | E46: мл | F46: =SUMIF('06_Нужно_заготовок'!$A:$A,A46,'06_Нужно_заготовок'!$E:$E) -> 0 | G46: =D46*F46 -> 0

Sheet 08_Итог_сырья
A1: Сырьё | B1: Базовая ед. | C1: Из меню напрямую | D1: Из заготовок | E1: Итого нужно | F1: Комментарий
A2: Игристое | B2: =IFERROR(INDEX('01_Номенклатура'!$C:$C,MATCH(A2,'01_Номенклатура'!$A:$A,0)),"") -> 0 | C2: =SUMIFS('05_Расход_меню'!$H:$H,'05_Расход_меню'!$C:$C,A2,'05_Расход_меню'!$D:$D,"Сырьё") -> 0 | D2: =SUMIFS('07_Расход_заготовок'!$G:$G,'07_Расход_заготовок'!$B:$B,A2,'07_Расход_заготовок'!$C:$C,"Сырьё") -> 0 | E2: =C2+D2 -> 0
A3: Аперитивы | B3: =IFERROR(INDEX('01_Номенклатура'!$C:$C,MATCH(A3,'01_Номенклатура'!$A:$A,0)),"") -> 0 | C3: =SUMIFS('05_Расход_меню'!$H:$H,'05_Расход_меню'!$C:$C,A3,'05_Расход_меню'!$D:$D,"Сырьё") -> 0 | D3: =SUMIFS('07_Расход_заготовок'!$G:$G,'07_Расход_заготовок'!$B:$B,A3,'07_Расход_заготовок'!$C:$C,"Сырьё") -> 0 | E3: =C3+D3 -> 0
A4: Содовая | B4: =IFERROR(INDEX('01_Номенклатура'!$C:$C,MATCH(A4,'01_Номенклатура'!$A:$A,0)),"") -> 0 | C4: =SUMIFS('05_Расход_меню'!$H:$H,'05_Расход_меню'!$C:$C,A4,'05_Расход_меню'!$D:$D,"Сырьё") -> 0 | D4: =SUMIFS('07_Расход_заготовок'!$G:$G,'07_Расход_заготовок'!$B:$B,A4,'07_Расход_заготовок'!$C:$C,"Сырьё") -> 0 | E4: =C4+D4 -> 0
A5: Сироп мохито | B5: =IFERROR(INDEX('01_Номенклатура'!$C:$C,MATCH(A5,'01_Номенклатура'!$A:$A,0)),"") -> 0 | C5: =SUMIFS('05_Расход_меню'!$H:$H,'05_Расход_меню'!$C:$C,A5,'05_Расход_меню'!$D:$D,"Сырьё") -> 0 | D5: =SUMIFS('07_Расход_заготовок'!$G:$G,'07_Расход_заготовок'!$B:$B,A5,'07_Расход_заготовок'!$C:$C,"Сырьё") -> 0 | E5: =C5+D5 -> 0
A6: Ром | B6: =IFERROR(INDEX('01_Номенклатура'!$C:$C,MATCH(A6,'01_Номенклатура'!$A:$A,0)),"") -> 0 | C6: =SUMIFS('05_Расход_меню'!$H:$H,'05_Расход_меню'!$C:$C,A6,'05_Расход_меню'!$D:$D,"Сырьё") -> 0 | D6: =SUMIFS('07_Расход_заготовок'!$G:$G,'07_Расход_заготовок'!$B:$B,A6,'07_Расход_заготовок'!$C:$C,"Сырьё") -> 0 | E6: =C6+D6 -> 0
A7: Сок лимона | B7: =IFERROR(INDEX('01_Номенклатура'!$C:$C,MATCH(A7,'01_Номенклатура'!$A:$A,0)),"") -> 0 | C7: =SUMIFS('05_Расход_меню'!$H:$H,'05_Расход_меню'!$C:$C,A7,'05_Расход_меню'!$D:$D,"Сырьё") -> 0 | D7: =SUMIFS('07_Расход_заготовок'!$G:$G,'07_Расход_заготовок'!$B:$B,A7,'07_Расход_заготовок'!$C:$C,"Сырьё") -> 0 | E7: =C7+D7 -> 0
A8: Мята | B8: =IFERROR(INDEX('01_Номенклатура'!$C:$C,MATCH(A8,'01_Номенклатура'!$A:$A,0)),"") -> 0 | C8: =SUMIFS('05_Расход_меню'!$H:$H,'05_Расход_меню'!$C:$C,A8,'05_Расход_меню'!$D:$D,"Сырьё") -> 0 | D8: =SUMIFS('07_Расход_заготовок'!$G:$G,'07_Расход_заготовок'!$B:$B,A8,'07_Расход_заготовок'!$C:$C,"Сырьё") -> 0 | E8: =C8+D8 -> 0
A9: Джин | B9: =IFERROR(INDEX('01_Номенклатура'!$C:$C,MATCH(A9,'01_Номенклатура'!$A:$A,0)),"") -> 0 | C9: =SUMIFS('05_Расход_меню'!$H:$H,'05_Расход_меню'!$C:$C,A9,'05_Расход_меню'!$D:$D,"Сырьё") -> 0 | D9: =SUMIFS('07_Расход_заготовок'!$G:$G,'07_Расход_заготовок'!$B:$B,A9,'07_Расход_заготовок'!$C:$C,"Сырьё") -> 0 | E9: =C9+D9 -> 0
A10: Красный базилик | B10: =IFERROR(INDEX('01_Номенклатура'!$C:$C,MATCH(A10,'01_Номенклатура'!$A:$A,0)),"") -> 0 | C10: =SUMIFS('05_Расход_меню'!$H:$H,'05_Расход_меню'!$C:$C,A10,'05_Расход_меню'!$D:$D,"Сырьё") -> 0 | D10: =SUMIFS('07_Расход_заготовок'!$G:$G,'07_Расход_заготовок'!$B:$B,A10,'07_Расход_заготовок'!$C:$C,"Сырьё") -> 0 | E10: =C10+D10 -> 0
A11: Арбузный лимонад | B11: =IFERROR(INDEX('01_Номенклатура'!$C:$C,MATCH(A11,'01_Номенклатура'!$A:$A,0)),"") -> 0 | C11: =SUMIFS('05_Расход_меню'!$H:$H,'05_Расход_меню'!$C:$C,A11,'05_Расход_меню'!$D:$D,"Сырьё") -> 0 | D11: =SUMIFS('07_Расход_заготовок'!$G:$G,'07_Расход_заготовок'!$B:$B,A11,'07_Расход_заготовок'!$C:$C,"Сырьё") -> 0 | E11: =C11+D11 -> 0
A12: Грушевая водка | B12: =IFERROR(INDEX('01_Номенклатура'!$C:$C,MATCH(A12,'01_Номенклатура'!$A:$A,0)),"") -> 0 | C12: =SUMIFS('05_Расход_меню'!$H:$H,'05_Расход_меню'!$C:$C,A12,'05_Расход_меню'!$D:$D,"Сырьё") -> 0 | D12: =SUMIFS('07_Расход_заготовок'!$G:$G,'07_Расход_заготовок'!$B:$B,A12,'07_Расход_заготовок'!$C:$C,"Сырьё") -> 0 | E12: =C12+D12 -> 0
A13: Сухой вермут | B13: =IFERROR(INDEX('01_Номенклатура'!$C:$C,MATCH(A13,'01_Номенклатура'!$A:$A,0)),"") -> 0 | C13: =SUMIFS('05_Расход_меню'!$H:$H,'05_Расход_меню'!$C:$C,A13,'05_Расход_меню'!$D:$D,"Сырьё") -> 0 | D13: =SUMIFS('07_Расход_заготовок'!$G:$G,'07_Расход_заготовок'!$B:$B,A13,'07_Расход_заготовок'!$C:$C,"Сырьё") -> 0 | E13: =C13+D13 -> 0
... A64: Ром/водка | B64: =IFERROR(INDEX('01_Номенклатура'!$C:$C,MATCH(A64,'01_Номенклатура'!$A:$A,0)),"") -> 0 | C64: =SUMIFS('05_Расход_меню'!$H:$H,'05_Расход_меню'!$C:$C,A64,'05_Расход_меню'!$D:$D,"Сырьё") -> 0 | D64: =SUMIFS('07_Расход_заготовок'!$G:$G,'07_Расход_заготовок'!$B:$B,A64,'07_Расход_заготовок'!$C:$C,"Сырьё") -> 0 | E64: =C64+D64 -> 0

Sheet 09_Список_покупок
A1: Купить | B1: Нужно | C1: Ед. | D1: Размер упаковки | E1: Закупочная ед. | F1: Купить упаковок | G1: Цена упаковки | H1: Сумма | I1: Комментарий
A2: Игристое | B2: =SUMIF('08_Итог_сырья'!$A:$A,A2,'08_Итог_сырья'!$E:$E) -> 0 | C2: =IFERROR(INDEX('01_Номенклатура'!$C:$C,MATCH(A2,'01_Номенклатура'!$A:$A,0)),"") -> 0 | D2: =IFERROR(INDEX('01_Номенклатура'!$E:$E,MATCH(A2,'01_Номенклатура'!$A:$A,0)),"") -> 0 | E2: =IFERROR(INDEX('01_Номенклатура'!$D:$D,MATCH(A2,'01_Номенклатура'!$A:$A,0)),"") -> 0 | F2: =IF(OR(B2=0,D2=""),"",ROUNDUP(B2/D2,0)) -> 0 | G2: =IFERROR(INDEX('01_Номенклатура'!$F:$F,MATCH(A2,'01_Номенклатура'!$A:$A,0)),"") -> 0 | H2: =IF(OR(F2="",G2=""),"",F2*G2) -> 0 | I2: =IF(D2="","заполнить размер упаковки","") -> 0
A3: Аперитивы | B3: =SUMIF('08_Итог_сырья'!$A:$A,A3,'08_Итог_сырья'!$E:$E) -> 0 | C3: =IFERROR(INDEX('01_Номенклатура'!$C:$C,MATCH(A3,'01_Номенклатура'!$A:$A,0)),"") -> 0 | D3: =IFERROR(INDEX('01_Номенклатура'!$E:$E,MATCH(A3,'01_Номенклатура'!$A:$A,0)),"") -> 0 | E3: =IFERROR(INDEX('01_Номенклатура'!$D:$D,MATCH(A3,'01_Номенклатура'!$A:$A,0)),"") -> 0 | F3: =IF(OR(B3=0,D3=""),"",ROUNDUP(B3/D3,0)) -> 0 | G3: =IFERROR(INDEX('01_Номенклатура'!$F:$F,MATCH(A3,'01_Номенклатура'!$A:$A,0)),"") -> 0 | H3: =IF(OR(F3="",G3=""),"",F3*G3) -> 0 | I3: =IF(D3="","заполнить размер упаковки","") -> 0
A4: Содовая | B4: =SUMIF('08_Итог_сырья'!$A:$A,A4,'08_Итог_сырья'!$E:$E) -> 0 | C4: =IFERROR(INDEX('01_Номенклатура'!$C:$C,MATCH(A4,'01_Номенклатура'!$A:$A,0)),"") -> 0 | D4: =IFERROR(INDEX('01_Номенклатура'!$E:$E,MATCH(A4,'01_Номенклатура'!$A:$A,0)),"") -> 0 | E4: =IFERROR(INDEX('01_Номенклатура'!$D:$D,MATCH(A4,'01_Номенклатура'!$A:$A,0)),"") -> 0 | F4: =IF(OR(B4=0,D4=""),"",ROUNDUP(B4/D4,0)) -> 0 | G4: =IFERROR(INDEX('01_Номенклатура'!$F:$F,MATCH(A4,'01_Номенклатура'!$A:$A,0)),"") -> 0 | H4: =IF(OR(F4="",G4=""),"",F4*G4) -> 0 | I4: =IF(D4="","заполнить размер упаковки","") -> 0
A5: Сироп мохито | B5: =SUMIF('08_Итог_сырья'!$A:$A,A5,'08_Итог_сырья'!$E:$E) -> 0 | C5: =IFERROR(INDEX('01_Номенклатура'!$C:$C,MATCH(A5,'01_Номенклатура'!$A:$A,0)),"") -> 0 | D5: =IFERROR(INDEX('01_Номенклатура'!$E:$E,MATCH(A5,'01_Номенклатура'!$A:$A,0)),"") -> 0 | E5: =IFERROR(INDEX('01_Номенклатура'!$D:$D,MATCH(A5,'01_Номенклатура'!$A:$A,0)),"") -> 0 | F5: =IF(OR(B5=0,D5=""),"",ROUNDUP(B5/D5,0)) -> 0 | G5: =IFERROR(INDEX('01_Номенклатура'!$F:$F,MATCH(A5,'01_Номенклатура'!$A:$A,0)),"") -> 0 | H5: =IF(OR(F5="",G5=""),"",F5*G5) -> 0 | I5: =IF(D5="","заполнить размер упаковки","") -> 0
A6: Ром | B6: =SUMIF('08_Итог_сырья'!$A:$A,A6,'08_Итог_сырья'!$E:$E) -> 0 | C6: =IFERROR(INDEX('01_Номенклатура'!$C:$C,MATCH(A6,'01_Номенклатура'!$A:$A,0)),"") -> 0 | D6: =IFERROR(INDEX('01_Номенклатура'!$E:$E,MATCH(A6,'01_Номенклатура'!$A:$A,0)),"") -> 0 | E6: =IFERROR(INDEX('01_Номенклатура'!$D:$D,MATCH(A6,'01_Номенклатура'!$A:$A,0)),"") -> 0 | F6: =IF(OR(B6=0,D6=""),"",ROUNDUP(B6/D6,0)) -> 0 | G6: =IFERROR(INDEX('01_Номенклатура'!$F:$F,MATCH(A6,'01_Номенклатура'!$A:$A,0)),"") -> 0 | H6: =IF(OR(F6="",G6=""),"",F6*G6) -> 0 | I6: =IF(D6="","заполнить размер упаковки","") -> 0
A7: Сок лимона | B7: =SUMIF('08_Итог_сырья'!$A:$A,A7,'08_Итог_сырья'!$E:$E) -> 0 | C7: =IFERROR(INDEX('01_Номенклатура'!$C:$C,MATCH(A7,'01_Номенклатура'!$A:$A,0)),"") -> 0 | D7: =IFERROR(INDEX('01_Номенклатура'!$E:$E,MATCH(A7,'01_Номенклатура'!$A:$A,0)),"") -> 0 | E7: =IFERROR(INDEX('01_Номенклатура'!$D:$D,MATCH(A7,'01_Номенклатура'!$A:$A,0)),"") -> 0 | F7: =IF(OR(B7=0,D7=""),"",ROUNDUP(B7/D7,0)) -> 0 | G7: =IFERROR(INDEX('01_Номенклатура'!$F:$F,MATCH(A7,'01_Номенклатура'!$A:$A,0)),"") -> 0 | H7: =IF(OR(F7="",G7=""),"",F7*G7) -> 0 | I7: =IF(D7="","заполнить размер упаковки","") -> 0
A8: Мята | B8: =SUMIF('08_Итог_сырья'!$A:$A,A8,'08_Итог_сырья'!$E:$E) -> 0 | C8: =IFERROR(INDEX('01_Номенклатура'!$C:$C,MATCH(A8,'01_Номенклатура'!$A:$A,0)),"") -> 0 | D8: =IFERROR(INDEX('01_Номенклатура'!$E:$E,MATCH(A8,'01_Номенклатура'!$A:$A,0)),"") -> 0 | E8: =IFERROR(INDEX('01_Номенклатура'!$D:$D,MATCH(A8,'01_Номенклатура'!$A:$A,0)),"") -> 0 | F8: =IF(OR(B8=0,D8=""),"",ROUNDUP(B8/D8,0)) -> 0 | G8: =IFERROR(INDEX('01_Номенклатура'!$F:$F,MATCH(A8,'01_Номенклатура'!$A:$A,0)),"") -> 0 | H8: =IF(OR(F8="",G8=""),"",F8*G8) -> 0 | I8: =IF(D8="","заполнить размер упаковки","") -> 0
A9: Джин | B9: =SUMIF('08_Итог_сырья'!$A:$A,A9,'08_Итог_сырья'!$E:$E) -> 0 | C9: =IFERROR(INDEX('01_Номенклатура'!$C:$C,MATCH(A9,'01_Номенклатура'!$A:$A,0)),"") -> 0 | D9: =IFERROR(INDEX('01_Номенклатура'!$E:$E,MATCH(A9,'01_Номенклатура'!$A:$A,0)),"") -> 0 | E9: =IFERROR(INDEX('01_Номенклатура'!$D:$D,MATCH(A9,'01_Номенклатура'!$A:$A,0)),"") -> 0 | F9: =IF(OR(B9=0,D9=""),"",ROUNDUP(B9/D9,0)) -> 0 | G9: =IFERROR(INDEX('01_Номенклатура'!$F:$F,MATCH(A9,'01_Номенклатура'!$A:$A,0)),"") -> 0 | H9: =IF(OR(F9="",G9=""),"",F9*G9) -> 0 | I9: =IF(D9="","заполнить размер упаковки","") -> 0
A10: Красный базилик | B10: =SUMIF('08_Итог_сырья'!$A:$A,A10,'08_Итог_сырья'!$E:$E) -> 0 | C10: =IFERROR(INDEX('01_Номенклатура'!$C:$C,MATCH(A10,'01_Номенклатура'!$A:$A,0)),"") -> 0 | D10: =IFERROR(INDEX('01_Номенклатура'!$E:$E,MATCH(A10,'01_Номенклатура'!$A:$A,0)),"") -> 0 | E10: =IFERROR(INDEX('01_Номенклатура'!$D:$D,MATCH(A10,'01_Номенклатура'!$A:$A,0)),"") -> 0 | F10: =IF(OR(B10=0,D10=""),"",ROUNDUP(B10/D10,0)) -> 0 | G10: =IFERROR(INDEX('01_Номенклатура'!$F:$F,MATCH(A10,'01_Номенклатура'!$A:$A,0)),"") -> 0 | H10: =IF(OR(F10="",G10=""),"",F10*G10) -> 0 | I10: =IF(D10="","заполнить размер упаковки","") -> 0
A11: Арбузный лимонад | B11: =SUMIF('08_Итог_сырья'!$A:$A,A11,'08_Итог_сырья'!$E:$E) -> 0 | C11: =IFERROR(INDEX('01_Номенклатура'!$C:$C,MATCH(A11,'01_Номенклатура'!$A:$A,0)),"") -> 0 | D11: =IFERROR(INDEX('01_Номенклатура'!$E:$E,MATCH(A11,'01_Номенклатура'!$A:$A,0)),"") -> 0 | E11: =IFERROR(INDEX('01_Номенклатура'!$D:$D,MATCH(A11,'01_Номенклатура'!$A:$A,0)),"") -> 0 | F11: =IF(OR(B11=0,D11=""),"",ROUNDUP(B11/D11,0)) -> 0 | G11: =IFERROR(INDEX('01_Номенклатура'!$F:$F,MATCH(A11,'01_Номенклатура'!$A:$A,0)),"") -> 0 | H11: =IF(OR(F11="",G11=""),"",F11*G11) -> 0 | I11: =IF(D11="","заполнить размер упаковки","") -> 0
A12: Грушевая водка | B12: =SUMIF('08_Итог_сырья'!$A:$A,A12,'08_Итог_сырья'!$E:$E) -> 0 | C12: =IFERROR(INDEX('01_Номенклатура'!$C:$C,MATCH(A12,'01_Номенклатура'!$A:$A,0)),"") -> 0 | D12: =IFERROR(INDEX('01_Номенклатура'!$E:$E,MATCH(A12,'01_Номенклатура'!$A:$A,0)),"") -> 0 | E12: =IFERROR(INDEX('01_Номенклатура'!$D:$D,MATCH(A12,'01_Номенклатура'!$A:$A,0)),"") -> 0 | F12: =IF(OR(B12=0,D12=""),"",ROUNDUP(B12/D12,0)) -> 0 | G12: =IFERROR(INDEX('01_Номенклатура'!$F:$F,MATCH(A12,'01_Номенклатура'!$A:$A,0)),"") -> 0 | H12: =IF(OR(F12="",G12=""),"",F12*G12) -> 0 | I12: =IF(D12="","заполнить размер упаковки","") -> 0
A13: Сухой вермут | B13: =SUMIF('08_Итог_сырья'!$A:$A,A13,'08_Итог_сырья'!$E:$E) -> 0 | C13: =IFERROR(INDEX('01_Номенклатура'!$C:$C,MATCH(A13,'01_Номенклатура'!$A:$A,0)),"") -> 0 | D13: =IFERROR(INDEX('01_Номенклатура'!$E:$E,MATCH(A13,'01_Номенклатура'!$A:$A,0)),"") -> 0 | E13: =IFERROR(INDEX('01_Номенклатура'!$D:$D,MATCH(A13,'01_Номенклатура'!$A:$A,0)),"") -> 0 | F13: =IF(OR(B13=0,D13=""),"",ROUNDUP(B13/D13,0)) -> 0 | G13: =IFERROR(INDEX('01_Номенклатура'!$F:$F,MATCH(A13,'01_Номенклатура'!$A:$A,0)),"") -> 0 | H13: =IF(OR(F13="",G13=""),"",F13*G13) -> 0 | I13: =IF(D13="","заполнить размер упаковки","") -> 0
... A64: Ром/водка | B64: =SUMIF('08_Итог_сырья'!$A:$A,A64,'08_Итог_сырья'!$E:$E) -> 0 | C64: =IFERROR(INDEX('01_Номенклатура'!$C:$C,MATCH(A64,'01_Номенклатура'!$A:$A,0)),"") -> 0 | D64: =IFERROR(INDEX('01_Номенклатура'!$E:$E,MATCH(A64,'01_Номенклатура'!$A:$A,0)),"") -> 0 | E64: =IFERROR(INDEX('01_Номенклатура'!$D:$D,MATCH(A64,'01_Номенклатура'!$A:$A,0)),"") -> 0 | F64: =IF(OR(B64=0,D64=""),"",ROUNDUP(B64/D64,0)) -> 0 | G64: =IFERROR(INDEX('01_Номенклатура'!$F:$F,MATCH(A64,'01_Номенклатура'!$A:$A,0)),"") -> 0 | H64: =IF(OR(F64="",G64=""),"",F64*G64) -> 0 | I64: =IF(D64="","заполнить размер упаковки","") -> 0
G67: Итого закупка: | H67: =SUM(H2:H64) -> 0

Sheet 10_Требует_уточнения
A1: Рецепт/позиция | B1: Ингредиент/поле | C1: Исходное значение | D1: Ед. | E1: Что уточнить
A2: Сприцы | B2: Содовая | C2: топом | D2: мл | E2: топом
A3: Мохито | B3: Мята | C3: 10 | D3: шт/веточка | E3: требуется единица/конвертация
A4: Мохито | B4: Содовая | C4: топом | D4: мл | E4: топом
A5: Клубничная ночь | B5: Содовая | C5: топом | D5: мл | E5: топом
A6: Арбуз и маракуйя | B6: Красный базилик | C6: 2 | D6: шт/веточка | E6: требуется единица/конвертация
A7: Арбуз и укроп | B7: Укроп | C7: 2 | D7: шт/веточка | E7: требуется единица/конвертация
A8: Арбуз и укроп | B8: Арбузный лимонад | C8: топом | D8: мл | E8: топом
A9: Бэзил смэш | B9: Базилик | C9: 3 | D9: шт/веточка | E9: требуется единица/конвертация
A10: Брекфаст мартини | B10: Мармелад | C10: 1 | E10: требуется единица/конвертация
A11: COSMOPOLITAN | B11: Пребэч | C11: 60 | E11: требуется единица/конвертация
A12: Баблгам 4 | B12: Бабл гам | C12: 20 | E12: требуется единица/конвертация
A13: Баблгам 5 | B13: Бабл гам | C13: 30 | E13: требуется единица/конвертация
A14: Баблгам 1 | B14: Бабл гам | C14: 30 | E14: требуется единица/конвертация
A15: Шот 1 | B15: Маринованный виноград | C15: 2 | E15: требуется единица/конвертация
A16: ШОТ 5 | B16: Мята | C16: 2 | D16: шт/веточка | E16: требуется единица/конвертация
A17: Настойка киви-мята | B17: Мята | C17: 10 | D17: шт/веточка | E17: требуется единица/конвертация
A18: Пюре маракуйи | B18: Сахар | C18: 250-400 | D18: г | E18: 250-400
A19: Пюре маракуйи | B19: Вода | C19: 250-400 | D19: мл | E19: 250-400
A20: Шисо кордиал | B20: Шисо листья | C20: 25 | E20: требуется единица/конвертация
A21: Настойка клубника каркаде | B21: ВЫХОД РЕЦЕПТА | D21: мл | E21: указать выход одной партии / общий объём настойки
A22: Настойка киви-мята | B22: ВЫХОД РЕЦЕПТА | D22: мл | E22: указать выход одной партии / общий объём настойки
A23: Настойка улун-малина | B23: ВЫХОД РЕЦЕПТА | D23: мл | E23: указать выход одной партии / общий объём настойки
A24: Настойка клубника корица | B24: ВЫХОД РЕЦЕПТА | D24: мл | E24: указать выход одной партии / общий объём настойки
A25: Содовая 1 | B25: ВЫХОД РЕЦЕПТА | D25: мл | E25: указать фактический выход заготовки; без этого сырьё заготовки не раскроется
A26: Клубничный сироп | B26: ВЫХОД РЕЦЕПТА | D26: мл | E26: указать фактический выход заготовки; без этого сырьё заготовки не раскроется
A27: Пюре маракуйи | B27: ВЫХОД РЕЦЕПТА | D27: мл | E27: указать фактический выход заготовки; без этого сырьё заготовки не раскроется
A28: Шисо кордиал | B28: ВЫХОД РЕЦЕПТА | D28: мл | E28: указать фактический выход заготовки; без этого сырьё заготовки не раскроется
A29: Мармелад | B29: ВЫХОД РЕЦЕПТА | D29: мл | E29: указать фактический выход заготовки; без этого сырьё заготовки не раскроется
A30: Пребэч | B30: ВЫХОД РЕЦЕПТА | D30: мл | E30: указать фактический выход заготовки; без этого сырьё заготовки не раскроется
A31: Щавелевый кордиал | B31: ВЫХОД РЕЦЕПТА | D31: мл | E31: указать фактический выход заготовки; без этого сырьё заготовки не раскроется
A32: Бабл гам | B32: ВЫХОД РЕЦЕПТА | D32: мл | E32: указать фактический выход заготовки; без этого сырьё заготовки не раскроется
A33: Пюре из персиков | B33: ВЫХОД РЕЦЕПТА | D33: мл | E33: указать фактический выход заготовки; без этого сырьё заготовки не раскроется

Sheet README
A1: Что я перенёс и где донастроить
A3: Перенесено | B3: 21 позиций меню/шотов/настоек, 9 заготовок, 134 строк рецептов.
A4: Ключевой лист для правки рецептов | B4: 03_Рецепты: одна строка = один ингредиент в одном рецепте.
A5: Ключевой лист для выбора | B5: 04_Выбор_меню: выбираешь Да/Нет и ручное количество, если нужно.
A6: Критично заполнить | B6: 02_Выходы_рецептов: выход каждой заготовки/настойки. Без этого не раскрывается сырьё премиксов.
A7: Критично заполнить | B7: 01_Номенклатура: размеры упаковок, цены, спорные единицы мяты/веточек/листов.
A8: Ограничение | B8: Модель раскрывает один уровень: позиция меню → заготовка → сырьё. Вложенные заготовки внутри заготовок показаны, но не раскрываются дальше автоматически.
A9: Спорные места | B9: 10_Требует_уточнения: диапазоны 250-400, топом, листочки/веточки и пустые выходы.
